<?xml version="1.0"?>
<robot name="cavex" xmlns:xacro="http://ros.org/wiki/xacro">

  <xacro:arg name="robot_name" default = "cavex"/>
  <xacro:arg name="external_urdf_loc" default=""/>
  <xacro:arg name="load_gazebo_configs" default="false"/>

  <xacro:property name="urdf_loc" value="$(arg external_urdf_loc)"/>

  <xacro:if value="$(arg load_gazebo_configs)">
    <xacro:include filename="$(find interbotix_xshexapod_gazebo)/config/interbotix_texture.gazebo"/>
  </xacro:if>

  <material name="interbotix_black">
    <texture filename="package://interbotix_xshexapod_descriptions/meshes/interbotix_black.png"/>
  </material>

  <xacro:macro name="leg" params="robot_name prefix x y yaw">

    <joint name="${prefix}_coxa" type="revolute">
      <axis xyz="0 0 1"/>
      <limit effort="2" lower="${radians(-55)}" upper="${radians(55)}" velocity="${pi}"/>
	<!-- should consider changing back to 3-->
      <origin rpy="0 0 ${yaw}" xyz="${x} ${y} 0"/>
      <parent link="${robot_name}/base_link"/>
      <child link="${robot_name}/${prefix}_coxa_link"/>
      <dynamics friction="0.5"/>
    </joint>

    <transmission name="trans_${prefix}_coxa">
      <type>transmission_interface/SimpleTransmission</type>
      <joint name="${prefix}_coxa">
        <hardwareInterface>hardware_interface/EffortJointInterface</hardwareInterface>
      </joint>
      <actuator name="${prefix}_coxa_motor">
        <mechanicalReduction>1</mechanicalReduction>
      </actuator>
    </transmission>

    <link name="${robot_name}/${prefix}_coxa_link">
      <visual>
        <origin rpy="0 0 0" xyz="0 0 0"/>
        <geometry>
          <mesh filename="package://interbotix_xshexapod_descriptions/meshes/cavex_meshes/2XL-430.stl" scale="0.001 0.001 0.001"/>
        </geometry>
        <material name="interbotix_black"/>
      </visual>
      <collision>
        <origin rpy="0 0 0" xyz="0 0 0"/>
        <geometry>
          <mesh filename="package://interbotix_xshexapod_descriptions/meshes/cavex_meshes/2XL-430.stl" scale="0.001 0.001 0.001"/>
        </geometry>
      </collision>
      <inertial>
        <origin rpy="0 0 0" xyz="0.019066 -0.000002 0.006577"/>
        <mass value="0.02471" />
        <inertia ixx="0.0000215400" iyy="0.00002657000" izz="0.00002925000" ixy="-0.00000000122" ixz="-0.00000192741" iyz="-0.00000000001" />
      </inertial>
    </link>

    <joint name="${prefix}_femur" type="revolute">
      <axis xyz="0 1 0"/>
      <limit effort="2" lower="${radians(-98)}" upper="${radians(90)}" velocity="${pi}"/>
	<!-- changed effort limit to 2 from 3 -->
      <origin rpy="0 0 0" xyz="0.0235 0 0"/>
      <parent link="${robot_name}/${prefix}_coxa_link"/>
      <child link="${robot_name}/${prefix}_femur_link"/>
      <dynamics friction="0.5"/>
    </joint>

    <transmission name="trans_${prefix}_femur">
      <type>transmission_interface/SimpleTransmission</type>
      <joint name="${prefix}_femur">
        <hardwareInterface>hardware_interface/EffortJointInterface</hardwareInterface>
      </joint>
      <actuator name="${prefix}_femur_motor">
        <mechanicalReduction>1</mechanicalReduction>
      </actuator>
    </transmission>

    <link name="${robot_name}/${prefix}_femur_link">
      <visual>oupSyncRead getdata failed
[ERROR] [1631254830.335948247]: g
        <origin rpy="0 0 0" xyz="0 0 0"/>
        <geometry>
          <mesh filename="package://interbotix_xshexapod_descriptions/meshes/cavex_meshes/topLegConnection.stl" scale="0.001 0.001 0.001"/>
        </geometry>
        <material name="interbotix_black"/>
      </visual>
      <collision>
        <origin rpy="0 0 0" xyz="0 0 0"/>
        <geometry>
          <mesh filename="package://interbotix_xshexapod_descriptions/meshes/cavex_meshes/topLegConnection.stl" scale="0.001 0.001 0.001"/>
        </geometry>
      </collision>
      <inertial>
        <origin rpy="0 0 0" xyz="0.020226 -0.00029 -0.00063"/>
        <mass value="0.085834" />
        <inertia ixx="0.0000288700" iyy="0.0000750200" izz="0.0000867200" ixy="0.0000002419" ixz="0.0000048494" iyz="0.0000000003" />
      </inertial>
    </link>

    <joint name="${prefix}_tibia" type="revolute">
      <axis xyz="0 1 0"/>
      <limit effort="2" lower="${radians(-45)}" upper="${radians(125)}" velocity="${pi}"/>
      <origin rpy="0 0 0" xyz="0.139 0 0"/>
      <parent link="${robot_name}/${prefix}_femur_link"/>
      <child link="${robot_name}/${prefix}_tibia_link"/>
      <dynamics friction="0.5"/>
    </joint>

    <transmission name="trans_${prefix}_tibia">
      <type>transmission_interface/SimpleTransmission</type>
      <joint name="${prefix}_tibia">
        <hardwareInterface>hardware_interface/EffortJointInterface</hardwareInterface>
      </joint>
      <actuator name="${prefix}_tibia_motor">
        <mechanicalReduction>1</mechanicalReduction>
      </actuator>
    </transmission>

    <link name="${robot_name}/${prefix}_tibia_link">
      <visual>
        <origin rpy="0 0 0" xyz="0 0 0"/>
        <geometry>
          <mesh filename="package://interbotix_xshexapod_descriptions/meshes/cavex_meshes/tibia.stl" scale="0.001 0.001 0.001"/>
        </geometry>
        <material name="interbotix_black"/>
      </visual>
      <collision>
        <origin rpy="0 0 0" xyz="0 0 0"/>
        <geometry>
          <mesh filename="package://interbotix_xshexapod_descriptions/meshes/cavex_meshes/tibia.stl" scale="0.001 0.001 0.001"/>
        </geometry>
      </collision>
      <inertial>
        <origin rpy="0 0 0" xyz="0.036797 0.000054 -0.011991"/>
        <mass value="0.171825" />
        <inertia ixx="0.0001762000" iyy="0.0005158000" izz="0.0003768000" ixy="-0.0000014522" ixz="0.0001789000" iyz="0.0000006181" />
      </inertial>
    </link>

    <joint name="${prefix}_foot" type="fixed">
      <origin rpy="0 0 0" xyz="0.191623 0 -0.00542439"/>
      <parent link="${robot_name}/${prefix}_tibia_link"/>
      <child link="${robot_name}/${prefix}_foot_link"/>
    </joint>

    <link name="${robot_name}/${prefix}_foot_link"/>

  </xacro:macro>

  <link name="$(arg robot_name)/base_link">
    <visual>
      <origin rpy="0 0 0" xyz="0 0 0"/>
      <geometry>
        <mesh filename="package://interbotix_xshexapod_descriptions/meshes/cavex_meshes/bodyAssembly.stl" scale="0.001 0.001 0.001"/>
      </geometry>
      <material name="interbotix_black"/>
    </visual>
    <collision>
      <origin rpy="0 0 0" xyz="0 0 0"/>
      <geometry>
        <mesh filename="package://interbotix_xshexapod_descriptions/meshes/cavex_meshes/bodyAssembly.stl" scale="0.001 0.001 0.001"/>
      </geometry>
    </collision>
    <inertial>
      <origin rpy="0 0 0" xyz="0.001522 0.000302 0.015345"/>
      <mass value="1.522054" />
      <inertia ixx="0.0044660000" iyy="0.0084890000" izz="0.0092020000" ixy="0.0000076888" ixz="-0.0001245000" iyz="0.0000050996" />
    </inertial>
  </link>

  <joint name="base_bottom" type="fixed">
    <origin rpy="0 0 0" xyz="0 0 -0.024"/>
    <!-- our original value was -0.0205, but changed to 0.024 after measuring-->	
    <parent link="$(arg robot_name)/base_link"/>
    <child link="$(arg robot_name)/base_bottom_link"/>
  </joint>

  <link name="$(arg robot_name)/base_bottom_link">
  </link>

  <xacro:leg robot_name="$(arg robot_name)" prefix="right_front" x="0.131636" y="-0.076" yaw="${-pi/6}"/>
  <xacro:leg robot_name="$(arg robot_name)" prefix="right_middle" x="0" y="-0.152" yaw="${-pi/2}"/>
  <xacro:leg robot_name="$(arg robot_name)" prefix="right_back" x="-0.131636" y="-0.076" yaw="${-5*pi/6}"/>
  <xacro:leg robot_name="$(arg robot_name)" prefix="left_front" x="0.131636" y="0.076" yaw="${pi/6}"/>
  <xacro:leg robot_name="$(arg robot_name)" prefix="left_middle" x="0" y="0.152" yaw="${pi/2}"/>
  <xacro:leg robot_name="$(arg robot_name)" prefix="left_back" x="-0.131636" y="0.076" yaw="${5*pi/6}"/>

  <xacro:if value="${urdf_loc != ''}">
    <xacro:include filename="${urdf_loc}"/>
  </xacro:if>

</robot>
